
2022-03-23 08:56:33,025 - [INFO] - __main__ - (main.py).main(32) - Сатана
2022-03-23 09:13:39,540 - [INFO] - __main__ - (main.py).main(32) - Создан лог файл
2022-03-23 09:14:51,286 - [INFO] - __main__ - (main.py).main(32) - Создан лог файл
2022-03-23 09:15:04,790 - [INFO] - __main__ - (main.py).main(32) - Создан лог файл
2022-03-23 09:20:28,680 - [INFO] - __main__ - (main.py).main(34) - Создан лог файл
2022-03-23 21:06:20,212 |     INFO | Создан лог файл
2022-03-23 21:12:12,330 |     INFO | Создан лог файл
2022-03-23 21:13:52,009 |     INFO | Создан лог файл
2022-03-23 21:14:28,751 |     INFO | Создан лог файл
2022-03-23 22:01:15,765 |     INFO | Создан лог файл
2022-03-23 22:01:41,965 |     INFO | Создан лог файл
2022-03-24 00:05:35,039 |     INFO | Создан лог файл
2022-03-24 00:09:02,259 |     INFO | Создан лог файл
2022-03-24 01:13:01,145 |    ERROR | 'Parser' object has no attribute 'header'
Traceback (most recent call last):
  File "c:\Users\ole lukoie\Desktop\my_parser\baseParser\control.py", line 8, in check
    return func(**kwargs)
  File "c:/Users/ole lukoie/Desktop/my_parser/Yarche/main.py", line 86, in main
    header=config.prod.header,
AttributeError: 'Parser' object has no attribute 'header'
2022-03-24 01:13:12,412 |    ERROR | get_session() got an unexpected keyword argument 'header'
Traceback (most recent call last):
  File "c:\Users\ole lukoie\Desktop\my_parser\baseParser\control.py", line 8, in check
    return func(**kwargs)
  File "c:/Users/ole lukoie/Desktop/my_parser/Yarche/main.py", line 87, in main
    proxy=proxy.get_proxy
TypeError: get_session() got an unexpected keyword argument 'header'
2022-03-24 01:13:26,270 |    ERROR | 'function' object has no attribute 'get'
Traceback (most recent call last):
  File "c:\Users\ole lukoie\Desktop\my_parser\baseParser\control.py", line 8, in check
    return func(**kwargs)
  File "c:/Users/ole lukoie/Desktop/my_parser/Yarche/main.py", line 87, in main
    proxy=proxy.get_proxy
  File "c:\Users\ole lukoie\Desktop\my_parser\baseParser\parse.py", line 17, in get_session
    proxies=proxy
  File "C:\python3.7\lib\site-packages\requests\sessions.py", line 555, in get
    return self.request('GET', url, **kwargs)
  File "C:\python3.7\lib\site-packages\requests\sessions.py", line 533, in request
    prep.url, proxies, stream, verify, cert
  File "C:\python3.7\lib\site-packages\requests\sessions.py", line 710, in merge_environment_settings
    no_proxy = proxies.get('no_proxy') if proxies is not None else None
AttributeError: 'function' object has no attribute 'get'
2022-03-24 01:15:27,132 |    ERROR | 'function' object has no attribute 'get'
Traceback (most recent call last):
  File "c:\Users\ole lukoie\Desktop\my_parser\baseParser\control.py", line 8, in check
    return func(**kwargs)
  File "c:/Users/ole lukoie/Desktop/my_parser/Yarche/main.py", line 87, in main
    proxy=proxy.get_proxy
  File "c:\Users\ole lukoie\Desktop\my_parser\baseParser\parse.py", line 18, in get_session
    proxies=proxy
  File "C:\python3.7\lib\site-packages\requests\sessions.py", line 555, in get
    return self.request('GET', url, **kwargs)
  File "C:\python3.7\lib\site-packages\requests\sessions.py", line 533, in request
    prep.url, proxies, stream, verify, cert
  File "C:\python3.7\lib\site-packages\requests\sessions.py", line 710, in merge_environment_settings
    no_proxy = proxies.get('no_proxy') if proxies is not None else None
AttributeError: 'function' object has no attribute 'get'
2022-03-24 01:15:43,497 |    ERROR | No connection adapters were found for "Parser(project_name='Ярче', base_url='https://yarcheplus.ru', cookies={})"
Traceback (most recent call last):
  File "c:\Users\ole lukoie\Desktop\my_parser\baseParser\control.py", line 8, in check
    return func(**kwargs)
  File "c:/Users/ole lukoie/Desktop/my_parser/Yarche/main.py", line 87, in main
    proxy=proxy.get_proxy()
  File "c:\Users\ole lukoie\Desktop\my_parser\baseParser\parse.py", line 18, in get_session
    proxies=proxy
  File "C:\python3.7\lib\site-packages\requests\sessions.py", line 555, in get
    return self.request('GET', url, **kwargs)
  File "C:\python3.7\lib\site-packages\requests\sessions.py", line 542, in request
    resp = self.send(prep, **send_kwargs)
  File "C:\python3.7\lib\site-packages\requests\sessions.py", line 649, in send
    adapter = self.get_adapter(url=request.url)
  File "C:\python3.7\lib\site-packages\requests\sessions.py", line 742, in get_adapter
    raise InvalidSchema("No connection adapters were found for {!r}".format(url))
requests.exceptions.InvalidSchema: No connection adapters were found for "Parser(project_name='Ярче', base_url='https://yarcheplus.ru', cookies={})"
2022-03-24 11:38:50,472 |    ERROR | expected string or bytes-like object
Traceback (most recent call last):
  File "c:\Users\ole lukoie\Desktop\my_parser\baseParser\control.py", line 8, in check
    return func(**kwargs)
  File "c:/Users/ole lukoie/Desktop/my_parser/Yarche/main.py", line 71, in main
    resptext=session.response
  File "c:\Users\ole lukoie\Desktop\my_parser\Yarche\buld.py", line 37, in get_json_from_html
    string=script
  File "C:\python3.7\lib\re.py", line 223, in findall
    return _compile(pattern, flags).findall(string)
TypeError: expected string or bytes-like object
2022-03-24 14:38:12,365 |    ERROR | HTTPSConnectionPool(host='yarcheplus.ru', port=443): Max retries exceeded with url: / (Caused by SSLError(SSLCertVerificationError(1, '[SSL: CERTIFICATE_VERIFY_FAILED] certificate verify failed: unable to get local issuer certificate (_ssl.c:1076)')))
Traceback (most recent call last):
  File "C:\python3.7\lib\site-packages\urllib3\connectionpool.py", line 706, in urlopen
    chunked=chunked,
  File "C:\python3.7\lib\site-packages\urllib3\connectionpool.py", line 382, in _make_request
    self._validate_conn(conn)
  File "C:\python3.7\lib\site-packages\urllib3\connectionpool.py", line 1010, in _validate_conn
    conn.connect()
  File "C:\python3.7\lib\site-packages\urllib3\connection.py", line 426, in connect
    tls_in_tls=tls_in_tls,
  File "C:\python3.7\lib\site-packages\urllib3\util\ssl_.py", line 450, in ssl_wrap_socket
    sock, context, tls_in_tls, server_hostname=server_hostname
  File "C:\python3.7\lib\site-packages\urllib3\util\ssl_.py", line 493, in _ssl_wrap_socket_impl
    return ssl_context.wrap_socket(sock, server_hostname=server_hostname)
  File "C:\python3.7\lib\ssl.py", line 423, in wrap_socket
    session=session
  File "C:\python3.7\lib\ssl.py", line 870, in _create
    self.do_handshake()
  File "C:\python3.7\lib\ssl.py", line 1139, in do_handshake
    self._sslobj.do_handshake()
ssl.SSLCertVerificationError: [SSL: CERTIFICATE_VERIFY_FAILED] certificate verify failed: unable to get local issuer certificate (_ssl.c:1076)

During handling of the above exception, another exception occurred:

Traceback (most recent call last):
  File "C:\python3.7\lib\site-packages\requests\adapters.py", line 449, in send
    timeout=timeout
  File "C:\python3.7\lib\site-packages\urllib3\connectionpool.py", line 756, in urlopen
    method, url, error=e, _pool=self, _stacktrace=sys.exc_info()[2]
  File "C:\python3.7\lib\site-packages\urllib3\util\retry.py", line 574, in increment
    raise MaxRetryError(_pool, url, error or ResponseError(cause))
urllib3.exceptions.MaxRetryError: HTTPSConnectionPool(host='yarcheplus.ru', port=443): Max retries exceeded with url: / (Caused by SSLError(SSLCertVerificationError(1, '[SSL: CERTIFICATE_VERIFY_FAILED] certificate verify failed: unable to get local issuer certificate (_ssl.c:1076)')))

During handling of the above exception, another exception occurred:

Traceback (most recent call last):
  File "c:\Users\ole lukoie\Desktop\my_parser\baseParser\control.py", line 8, in check
    return func(**kwargs)
  File "c:/Users/ole lukoie/Desktop/my_parser/Yarche/main.py", line 67, in main
    proxy=proxy.get_proxy()
  File "c:\Users\ole lukoie\Desktop\my_parser\baseParser\parse.py", line 18, in get_session
    proxies=proxy)
  File "C:\python3.7\lib\site-packages\requests\sessions.py", line 555, in get
    return self.request('GET', url, **kwargs)
  File "C:\python3.7\lib\site-packages\requests\sessions.py", line 542, in request
    resp = self.send(prep, **send_kwargs)
  File "C:\python3.7\lib\site-packages\requests\sessions.py", line 655, in send
    r = adapter.send(request, **kwargs)
  File "C:\python3.7\lib\site-packages\requests\adapters.py", line 514, in send
    raise SSLError(e, request=request)
requests.exceptions.SSLError: HTTPSConnectionPool(host='yarcheplus.ru', port=443): Max retries exceeded with url: / (Caused by SSLError(SSLCertVerificationError(1, '[SSL: CERTIFICATE_VERIFY_FAILED] certificate verify failed: unable to get local issuer certificate (_ssl.c:1076)')))
2022-03-24 14:41:57,087 |    ERROR | HTTPSConnectionPool(host='yarcheplus.ru', port=443): Max retries exceeded with url: / (Caused by SSLError(SSLCertVerificationError(1, '[SSL: CERTIFICATE_VERIFY_FAILED] certificate verify failed: unable to get local issuer certificate (_ssl.c:1076)')))
Traceback (most recent call last):
  File "C:\python3.7\lib\site-packages\urllib3\connectionpool.py", line 706, in urlopen
    chunked=chunked,
  File "C:\python3.7\lib\site-packages\urllib3\connectionpool.py", line 382, in _make_request
    self._validate_conn(conn)
  File "C:\python3.7\lib\site-packages\urllib3\connectionpool.py", line 1010, in _validate_conn
    conn.connect()
  File "C:\python3.7\lib\site-packages\urllib3\connection.py", line 426, in connect
    tls_in_tls=tls_in_tls,
  File "C:\python3.7\lib\site-packages\urllib3\util\ssl_.py", line 450, in ssl_wrap_socket
    sock, context, tls_in_tls, server_hostname=server_hostname
  File "C:\python3.7\lib\site-packages\urllib3\util\ssl_.py", line 493, in _ssl_wrap_socket_impl
    return ssl_context.wrap_socket(sock, server_hostname=server_hostname)
  File "C:\python3.7\lib\ssl.py", line 423, in wrap_socket
    session=session
  File "C:\python3.7\lib\ssl.py", line 870, in _create
    self.do_handshake()
  File "C:\python3.7\lib\ssl.py", line 1139, in do_handshake
    self._sslobj.do_handshake()
ssl.SSLCertVerificationError: [SSL: CERTIFICATE_VERIFY_FAILED] certificate verify failed: unable to get local issuer certificate (_ssl.c:1076)

During handling of the above exception, another exception occurred:

Traceback (most recent call last):
  File "C:\python3.7\lib\site-packages\requests\adapters.py", line 449, in send
    timeout=timeout
  File "C:\python3.7\lib\site-packages\urllib3\connectionpool.py", line 756, in urlopen
    method, url, error=e, _pool=self, _stacktrace=sys.exc_info()[2]
  File "C:\python3.7\lib\site-packages\urllib3\util\retry.py", line 574, in increment
    raise MaxRetryError(_pool, url, error or ResponseError(cause))
urllib3.exceptions.MaxRetryError: HTTPSConnectionPool(host='yarcheplus.ru', port=443): Max retries exceeded with url: / (Caused by SSLError(SSLCertVerificationError(1, '[SSL: CERTIFICATE_VERIFY_FAILED] certificate verify failed: unable to get local issuer certificate (_ssl.c:1076)')))

During handling of the above exception, another exception occurred:

Traceback (most recent call last):
  File "c:\Users\ole lukoie\Desktop\my_parser\baseParser\control.py", line 8, in check
    return func(**kwargs)
  File "c:/Users/ole lukoie/Desktop/my_parser/Yarche/main.py", line 67, in main
    proxy=proxy.get_proxy()
  File "c:\Users\ole lukoie\Desktop\my_parser\baseParser\parse.py", line 18, in get_session
    proxies=proxy)
  File "C:\python3.7\lib\site-packages\requests\sessions.py", line 555, in get
    return self.request('GET', url, **kwargs)
  File "C:\python3.7\lib\site-packages\requests\sessions.py", line 542, in request
    resp = self.send(prep, **send_kwargs)
  File "C:\python3.7\lib\site-packages\requests\sessions.py", line 655, in send
    r = adapter.send(request, **kwargs)
  File "C:\python3.7\lib\site-packages\requests\adapters.py", line 514, in send
    raise SSLError(e, request=request)
requests.exceptions.SSLError: HTTPSConnectionPool(host='yarcheplus.ru', port=443): Max retries exceeded with url: / (Caused by SSLError(SSLCertVerificationError(1, '[SSL: CERTIFICATE_VERIFY_FAILED] certificate verify failed: unable to get local issuer certificate (_ssl.c:1076)')))
2022-03-24 14:58:13,615 |    ERROR | get() missing 1 required positional argument: 'key'
Traceback (most recent call last):
  File "c:\Users\ole lukoie\Desktop\my_parser\baseParser\control.py", line 8, in check
    return func(**kwargs)
  File "c:/Users/ole lukoie/Desktop/my_parser/Yarche/main.py", line 71, in main
    resptext=session.response
  File "c:\Users\ole lukoie\Desktop\my_parser\Yarche\buld.py", line 33, in get_json_from_html
    print(script.get())
TypeError: get() missing 1 required positional argument: 'key'
2022-03-24 15:04:25,335 |    ERROR | 'NoneType' object has no attribute 'text'
Traceback (most recent call last):
  File "c:\Users\ole lukoie\Desktop\my_parser\baseParser\control.py", line 8, in check
    return func(**kwargs)
  File "c:/Users/ole lukoie/Desktop/my_parser/Yarche/main.py", line 71, in main
    resptext=session.response
  File "c:\Users\ole lukoie\Desktop\my_parser\Yarche\buld.py", line 35, in get_json_from_html
    print(script.text)
AttributeError: 'NoneType' object has no attribute 'text'
2022-03-24 15:05:15,584 |    ERROR | 'NoneType' object has no attribute 'text'
Traceback (most recent call last):
  File "c:\Users\ole lukoie\Desktop\my_parser\baseParser\control.py", line 8, in check
    return func(**kwargs)
  File "c:/Users/ole lukoie/Desktop/my_parser/Yarche/main.py", line 71, in main
    resptext=session.response
  File "c:\Users\ole lukoie\Desktop\my_parser\Yarche\buld.py", line 35, in get_json_from_html
    print(script.text)
AttributeError: 'NoneType' object has no attribute 'text'
2022-03-24 15:05:50,740 |    ERROR | 'NoneType' object has no attribute 'text'
Traceback (most recent call last):
  File "c:\Users\ole lukoie\Desktop\my_parser\baseParser\control.py", line 8, in check
    return func(**kwargs)
  File "c:/Users/ole lukoie/Desktop/my_parser/Yarche/main.py", line 71, in main
    resptext=session.response
  File "c:\Users\ole lukoie\Desktop\my_parser\Yarche\buld.py", line 35, in get_json_from_html
    print(script.text)
AttributeError: 'NoneType' object has no attribute 'text'
2022-03-24 15:09:15,340 |    ERROR | get_json_from_html() got an unexpected keyword argument 'resptext'
Traceback (most recent call last):
  File "c:\Users\ole lukoie\Desktop\my_parser\baseParser\control.py", line 8, in check
    return func(**kwargs)
  File "c:/Users/ole lukoie/Desktop/my_parser/Yarche/main.py", line 71, in main
    resptext=session.response
TypeError: get_json_from_html() got an unexpected keyword argument 'resptext'
2022-03-26 16:11:30,588 |    ERROR | 'ParseYarche' object has no attribute 'get_coordinats'
Traceback (most recent call last):
  File "c:\Users\ole lukoie\Desktop\my_parser\baseParser\control.py", line 8, in check
    return func(**kwargs)
  File "c:/Users/ole lukoie/Desktop/my_parser/Yarche/main.py", line 49, in main
    proxy=proxy)
  File "c:\Users\ole lukoie\Desktop\my_parser\Yarche\buld.py", line 21, in __init__
    3:{"fucn":self.get_coordinats},
AttributeError: 'ParseYarche' object has no attribute 'get_coordinats'
2022-03-26 16:13:47,818 |    ERROR | CENTER() missing 1 required positional argument: 'itap'
Traceback (most recent call last):
  File "c:\Users\ole lukoie\Desktop\my_parser\baseParser\control.py", line 8, in check
    return func(**kwargs)
  File "c:/Users/ole lukoie/Desktop/my_parser/Yarche/main.py", line 50, in main
    parser.CENTER()
TypeError: CENTER() missing 1 required positional argument: 'itap'
2022-03-26 16:14:00,913 |    ERROR | 'Proxy' object has no attribute 'getProxy'
Traceback (most recent call last):
  File "c:\Users\ole lukoie\Desktop\my_parser\baseParser\control.py", line 8, in check
    return func(**kwargs)
  File "c:/Users/ole lukoie/Desktop/my_parser/Yarche/main.py", line 50, in main
    parser.CENTER()
  File "c:\Users\ole lukoie\Desktop\my_parser\Yarche\buld.py", line 29, in CENTER
    proxy=self.proxy.getProxy()
AttributeError: 'Proxy' object has no attribute 'getProxy'
2022-03-26 16:15:07,526 |    ERROR | __init__() got an unexpected keyword argument 'proxy'
Traceback (most recent call last):
  File "c:\Users\ole lukoie\Desktop\my_parser\baseParser\control.py", line 8, in check
    return func(**kwargs)
  File "c:/Users/ole lukoie/Desktop/my_parser/Yarche/main.py", line 45, in main
    proxy = ProxyPull(proxy=None)
TypeError: __init__() got an unexpected keyword argument 'proxy'
2022-03-26 16:15:39,451 |    ERROR | __init__() got an unexpected keyword argument 'proxy'
Traceback (most recent call last):
  File "c:\Users\ole lukoie\Desktop\my_parser\baseParser\control.py", line 8, in check
    return func(**kwargs)
  File "c:/Users/ole lukoie/Desktop/my_parser/Yarche/main.py", line 45, in main
    proxy = ProxyPull(proxy=None)
TypeError: __init__() got an unexpected keyword argument 'proxy'
2022-03-26 16:56:08,717 |    ERROR | HTTPSConnectionPool(host='yarcheplus.ru', port=443): Max retries exceeded with url: / (Caused by SSLError(SSLCertVerificationError(1, '[SSL: CERTIFICATE_VERIFY_FAILED] certificate verify failed: unable to get local issuer certificate (_ssl.c:1076)')))
Traceback (most recent call last):
  File "C:\python3.7\lib\site-packages\urllib3\connectionpool.py", line 706, in urlopen
    chunked=chunked,
  File "C:\python3.7\lib\site-packages\urllib3\connectionpool.py", line 382, in _make_request
    self._validate_conn(conn)
  File "C:\python3.7\lib\site-packages\urllib3\connectionpool.py", line 1010, in _validate_conn
    conn.connect()
  File "C:\python3.7\lib\site-packages\urllib3\connection.py", line 426, in connect
    tls_in_tls=tls_in_tls,
  File "C:\python3.7\lib\site-packages\urllib3\util\ssl_.py", line 450, in ssl_wrap_socket
    sock, context, tls_in_tls, server_hostname=server_hostname
  File "C:\python3.7\lib\site-packages\urllib3\util\ssl_.py", line 493, in _ssl_wrap_socket_impl
    return ssl_context.wrap_socket(sock, server_hostname=server_hostname)
  File "C:\python3.7\lib\ssl.py", line 423, in wrap_socket
    session=session
  File "C:\python3.7\lib\ssl.py", line 870, in _create
    self.do_handshake()
  File "C:\python3.7\lib\ssl.py", line 1139, in do_handshake
    self._sslobj.do_handshake()
ssl.SSLCertVerificationError: [SSL: CERTIFICATE_VERIFY_FAILED] certificate verify failed: unable to get local issuer certificate (_ssl.c:1076)

During handling of the above exception, another exception occurred:

Traceback (most recent call last):
  File "C:\python3.7\lib\site-packages\requests\adapters.py", line 449, in send
    timeout=timeout
  File "C:\python3.7\lib\site-packages\urllib3\connectionpool.py", line 756, in urlopen
    method, url, error=e, _pool=self, _stacktrace=sys.exc_info()[2]
  File "C:\python3.7\lib\site-packages\urllib3\util\retry.py", line 574, in increment
    raise MaxRetryError(_pool, url, error or ResponseError(cause))
urllib3.exceptions.MaxRetryError: HTTPSConnectionPool(host='yarcheplus.ru', port=443): Max retries exceeded with url: / (Caused by SSLError(SSLCertVerificationError(1, '[SSL: CERTIFICATE_VERIFY_FAILED] certificate verify failed: unable to get local issuer certificate (_ssl.c:1076)')))

During handling of the above exception, another exception occurred:

Traceback (most recent call last):
  File "c:\Users\ole lukoie\Desktop\my_parser\baseParser\control.py", line 8, in check
    return func(**kwargs)
  File "c:/Users/ole lukoie/Desktop/my_parser/Yarche/main.py", line 50, in main
    parser.CENTER()
  File "c:\Users\ole lukoie\Desktop\my_parser\Yarche\buld.py", line 31, in CENTER
    proxy=self.proxy.getProxy()
  File "c:\Users\ole lukoie\Desktop\my_parser\baseParser\parse.py", line 17, in get_session
    proxies=proxy)
  File "C:\python3.7\lib\site-packages\requests\sessions.py", line 555, in get
    return self.request('GET', url, **kwargs)
  File "C:\python3.7\lib\site-packages\requests\sessions.py", line 542, in request
    resp = self.send(prep, **send_kwargs)
  File "C:\python3.7\lib\site-packages\requests\sessions.py", line 655, in send
    r = adapter.send(request, **kwargs)
  File "C:\python3.7\lib\site-packages\requests\adapters.py", line 514, in send
    raise SSLError(e, request=request)
requests.exceptions.SSLError: HTTPSConnectionPool(host='yarcheplus.ru', port=443): Max retries exceeded with url: / (Caused by SSLError(SSLCertVerificationError(1, '[SSL: CERTIFICATE_VERIFY_FAILED] certificate verify failed: unable to get local issuer certificate (_ssl.c:1076)')))
2022-03-26 16:57:17,915 |    ERROR | 'ParseYarche' object has no attribute 'token'
Traceback (most recent call last):
  File "c:\Users\ole lukoie\Desktop\my_parser\baseParser\control.py", line 8, in check
    return func(**kwargs)
  File "c:/Users/ole lukoie/Desktop/my_parser/Yarche/main.py", line 50, in main
    parser.CENTER()
  File "c:\Users\ole lukoie\Desktop\my_parser\Yarche\buld.py", line 34, in CENTER
    print(self.token)
AttributeError: 'ParseYarche' object has no attribute 'token'
2022-03-26 16:57:33,609 |    ERROR | 'Parser' object has no attribute 'ad'
Traceback (most recent call last):
  File "c:\Users\ole lukoie\Desktop\my_parser\baseParser\control.py", line 8, in check
    return func(**kwargs)
  File "c:/Users/ole lukoie/Desktop/my_parser/Yarche/main.py", line 50, in main
    parser.CENTER()
  File "c:\Users\ole lukoie\Desktop\my_parser\Yarche\buld.py", line 34, in CENTER
    self.getCoordinat(adress=self.config.prod.ad)
AttributeError: 'Parser' object has no attribute 'ad'
2022-03-26 16:58:03,553 |    ERROR | can only concatenate str (not "dict") to str
Traceback (most recent call last):
  File "c:\Users\ole lukoie\Desktop\my_parser\baseParser\control.py", line 8, in check
    return func(**kwargs)
  File "c:/Users/ole lukoie/Desktop/my_parser/Yarche/main.py", line 50, in main
    parser.CENTER()
  File "c:\Users\ole lukoie\Desktop\my_parser\Yarche\buld.py", line 34, in CENTER
    self.getCoordinat(adress=self.config.prod.Adress[0])
  File "c:\Users\ole lukoie\Desktop\my_parser\Yarche\buld.py", line 45, in getCoordinat
    "variables": "{\"input\":{\"search\":\"" + adress + " \"}}"
TypeError: can only concatenate str (not "dict") to str
2022-03-26 17:24:24,348 |    ERROR | list index out of range
Traceback (most recent call last):
  File "c:\Users\ole lukoie\Desktop\my_parser\baseParser\control.py", line 8, in check
    return func(**kwargs)
  File "c:/Users/ole lukoie/Desktop/my_parser/Yarche/main.py", line 50, in main
    parser.CENTER()
  File "c:\Users\ole lukoie\Desktop\my_parser\Yarche\buld.py", line 33, in CENTER
    self.get_token()
  File "c:\Users\ole lukoie\Desktop\my_parser\Yarche\buld.py", line 43, in get_token
    string=self.session.response)[0]
IndexError: list index out of range
2022-03-26 18:45:41,939 |    ERROR | 'lat'
Traceback (most recent call last):
  File "c:\Users\ole lukoie\Desktop\my_parser\baseParser\control.py", line 8, in check
    return func(**kwargs)
  File "c:/Users/ole lukoie/Desktop/my_parser/Yarche/main.py", line 50, in main
    parser.CENTER()
  File "c:\Users\ole lukoie\Desktop\my_parser\Yarche\buld.py", line 31, in CENTER
    self.get_coordinats(adress=self.config.prod.Adress[0])
  File "c:\Users\ole lukoie\Desktop\my_parser\Yarche\buld.py", line 52, in get_coordinats
    response.json()["lat"],
KeyError: 'lat'
2022-03-26 18:47:31,192 |    ERROR | tuple indices must be integers or slices, not str
Traceback (most recent call last):
  File "c:\Users\ole lukoie\Desktop\my_parser\baseParser\control.py", line 8, in check
    return func(**kwargs)
  File "c:/Users/ole lukoie/Desktop/my_parser/Yarche/main.py", line 50, in main
    parser.CENTER()
  File "c:\Users\ole lukoie\Desktop\my_parser\Yarche\buld.py", line 32, in CENTER
    self.set_adress(adress=self.config.prod.Adress[0])
  File "c:\Users\ole lukoie\Desktop\my_parser\Yarche\buld.py", line 67, in set_adress
    self.coordinats['long'] + "},\"isAccurate\":true,\"isPrivateHouse\":false}}"},
TypeError: tuple indices must be integers or slices, not str
2022-03-26 18:48:07,848 |    ERROR | can only concatenate str (not "float") to str
Traceback (most recent call last):
  File "c:\Users\ole lukoie\Desktop\my_parser\baseParser\control.py", line 8, in check
    return func(**kwargs)
  File "c:/Users/ole lukoie/Desktop/my_parser/Yarche/main.py", line 50, in main
    parser.CENTER()
  File "c:\Users\ole lukoie\Desktop\my_parser\Yarche\buld.py", line 32, in CENTER
    self.set_adress(adress=self.config.prod.Adress[0])
  File "c:\Users\ole lukoie\Desktop\my_parser\Yarche\buld.py", line 67, in set_adress
    self.coordinats[1] + "},\"isAccurate\":true,\"isPrivateHouse\":false}}"},
TypeError: can only concatenate str (not "float") to str
2022-03-26 21:27:20,688 |    ERROR | HTTPSConnectionPool(host='api.magonline.ru', port=443): Max retries exceeded with url: /api/graphql (Caused by SSLError(SSLCertVerificationError(1, '[SSL: CERTIFICATE_VERIFY_FAILED] certificate verify failed: unable to get local issuer certificate (_ssl.c:1076)')))
Traceback (most recent call last):
  File "C:\python3.7\lib\site-packages\urllib3\connectionpool.py", line 706, in urlopen
    chunked=chunked,
  File "C:\python3.7\lib\site-packages\urllib3\connectionpool.py", line 382, in _make_request
    self._validate_conn(conn)
  File "C:\python3.7\lib\site-packages\urllib3\connectionpool.py", line 1010, in _validate_conn
    conn.connect()
  File "C:\python3.7\lib\site-packages\urllib3\connection.py", line 426, in connect
    tls_in_tls=tls_in_tls,
  File "C:\python3.7\lib\site-packages\urllib3\util\ssl_.py", line 450, in ssl_wrap_socket
    sock, context, tls_in_tls, server_hostname=server_hostname
  File "C:\python3.7\lib\site-packages\urllib3\util\ssl_.py", line 493, in _ssl_wrap_socket_impl
    return ssl_context.wrap_socket(sock, server_hostname=server_hostname)
  File "C:\python3.7\lib\ssl.py", line 423, in wrap_socket
    session=session
  File "C:\python3.7\lib\ssl.py", line 870, in _create
    self.do_handshake()
  File "C:\python3.7\lib\ssl.py", line 1139, in do_handshake
    self._sslobj.do_handshake()
ssl.SSLCertVerificationError: [SSL: CERTIFICATE_VERIFY_FAILED] certificate verify failed: unable to get local issuer certificate (_ssl.c:1076)

During handling of the above exception, another exception occurred:

Traceback (most recent call last):
  File "C:\python3.7\lib\site-packages\requests\adapters.py", line 449, in send
    timeout=timeout
  File "C:\python3.7\lib\site-packages\urllib3\connectionpool.py", line 756, in urlopen
    method, url, error=e, _pool=self, _stacktrace=sys.exc_info()[2]
  File "C:\python3.7\lib\site-packages\urllib3\util\retry.py", line 574, in increment
    raise MaxRetryError(_pool, url, error or ResponseError(cause))
urllib3.exceptions.MaxRetryError: HTTPSConnectionPool(host='api.magonline.ru', port=443): Max retries exceeded with url: /api/graphql (Caused by SSLError(SSLCertVerificationError(1, '[SSL: CERTIFICATE_VERIFY_FAILED] certificate verify failed: unable to get local issuer certificate (_ssl.c:1076)')))

During handling of the above exception, another exception occurred:

Traceback (most recent call last):
  File "c:\Users\ole lukoie\Desktop\my_parser\baseParser\control.py", line 8, in check
    return func(**kwargs)
  File "c:/Users/ole lukoie/Desktop/my_parser/Yarche/main.py", line 50, in main
    parser.CENTER()
  File "c:\Users\ole lukoie\Desktop\my_parser\Yarche\buld.py", line 28, in CENTER
    self.parse_product_category()
  File "c:\Users\ole lukoie\Desktop\my_parser\Yarche\buld.py", line 95, in parse_product_category
    json={"query":"\n  query ($input: RecommendationsInput!) {\n    recommendations (input: $input) {\n      list {\n  id\n  code\n  name\n  description\n  amount\n  image {\n  id\n  title\n  alt\n}\n  price\n  previousPrice\n  itemSum\n  isNew\n  isHit\n  isVkusvill\n  isFavorite\n  isAvailable\n  isSubscribed\n  isVeterinaryControl\n  quant {\n  code\n  fullName\n  shortName\n  multiple\n  pricePerUnit\n  previousPricePerUnit\n  unit\n  type\n  minAmount\n  stepAmount\n  currency\n}\n  categories {\n  id\n  name\n  code\n  treeId\n  parentTreeId\n}\n  rating\n  numberOfRatings\n}\n      page {\n  total\n  limit\n  page\n}\n    }\n  }\n","variables":"{\"input\":{\"categoryIds\":[687],\"type\":\"categoriesBestsellers\",\"page\":{\"page\":1,\"limit\":12}}}"})
  File "C:\python3.7\lib\site-packages\requests\sessions.py", line 590, in post
    return self.request('POST', url, data=data, json=json, **kwargs)
  File "C:\python3.7\lib\site-packages\requests\sessions.py", line 542, in request
    resp = self.send(prep, **send_kwargs)
  File "C:\python3.7\lib\site-packages\requests\sessions.py", line 655, in send
    r = adapter.send(request, **kwargs)
  File "C:\python3.7\lib\site-packages\requests\adapters.py", line 514, in send
    raise SSLError(e, request=request)
requests.exceptions.SSLError: HTTPSConnectionPool(host='api.magonline.ru', port=443): Max retries exceeded with url: /api/graphql (Caused by SSLError(SSLCertVerificationError(1, '[SSL: CERTIFICATE_VERIFY_FAILED] certificate verify failed: unable to get local issuer certificate (_ssl.c:1076)')))
2022-03-27 01:47:05,286 |    ERROR | 'data'
Traceback (most recent call last):
  File "c:\Users\ole lukoie\Desktop\my_parser\baseParser\control.py", line 8, in check
    return func(**kwargs)
  File "c:/Users/ole lukoie/Desktop/my_parser/Yarche/main.py", line 50, in main
    parser.CENTER()
  File "c:\Users\ole lukoie\Desktop\my_parser\Yarche\buld.py", line 33, in CENTER
    self.check_category()
  File "c:\Users\ole lukoie\Desktop\my_parser\Yarche\buld.py", line 90, in check_category
    self.before_category = response.json()['data']['categories']
KeyError: 'data'
2022-03-27 01:50:50,700 |    ERROR | 'data'
Traceback (most recent call last):
  File "c:\Users\ole lukoie\Desktop\my_parser\baseParser\control.py", line 8, in check
    return func(**kwargs)
  File "c:/Users/ole lukoie/Desktop/my_parser/Yarche/main.py", line 50, in main
    parser.CENTER()
  File "c:\Users\ole lukoie\Desktop\my_parser\Yarche\buld.py", line 33, in CENTER
    self.check_category()
  File "c:\Users\ole lukoie\Desktop\my_parser\Yarche\buld.py", line 95, in check_category
    self.before_category = response.json()['data']['categories']
KeyError: 'data'
2022-03-27 01:56:40,716 |    ERROR | 'amo'
Traceback (most recent call last):
  File "c:\Users\ole lukoie\Desktop\my_parser\baseParser\control.py", line 8, in check
    return func(**kwargs)
  File "c:/Users/ole lukoie/Desktop/my_parser/Yarche/main.py", line 50, in main
    parser.CENTER()
  File "c:\Users\ole lukoie\Desktop\my_parser\Yarche\buld.py", line 34, in CENTER
    self.parse_product_category()
  File "c:\Users\ole lukoie\Desktop\my_parser\Yarche\buld.py", line 105, in parse_product_category
    json=data_for_get_products(category_id=category['id'], limit=category['amo']),
KeyError: 'amo'
2022-03-27 02:19:41,281 |    ERROR | 'int' object is not subscriptable
Traceback (most recent call last):
  File "c:\Users\ole lukoie\Desktop\my_parser\baseParser\control.py", line 8, in check
    return func(**kwargs)
  File "c:/Users/ole lukoie/Desktop/my_parser/Yarche/main.py", line 50, in main
    parser.CENTER()
  File "c:\Users\ole lukoie\Desktop\my_parser\Yarche\buld.py", line 36, in CENTER
    self.parse_product_category()
  File "c:\Users\ole lukoie\Desktop\my_parser\Yarche\buld.py", line 103, in parse_product_category
    json=data_for_get_products(category_id=category['id'], limit=category['amount']),
TypeError: 'int' object is not subscriptable
2022-03-27 02:20:13,753 |    ERROR | 'int' object is not subscriptable
Traceback (most recent call last):
  File "c:\Users\ole lukoie\Desktop\my_parser\baseParser\control.py", line 8, in check
    return func(**kwargs)
  File "c:/Users/ole lukoie/Desktop/my_parser/Yarche/main.py", line 50, in main
    parser.CENTER()
  File "c:\Users\ole lukoie\Desktop\my_parser\Yarche\buld.py", line 36, in CENTER
    self.parse_product_category()
  File "c:\Users\ole lukoie\Desktop\my_parser\Yarche\buld.py", line 103, in parse_product_category
    json=data_for_get_products(category_id=category['id'], limit=category['amount']),
TypeError: 'int' object is not subscriptable
2022-03-27 02:23:43,132 |    ERROR | 'int' object is not subscriptable
Traceback (most recent call last):
  File "c:\Users\ole lukoie\Desktop\my_parser\baseParser\control.py", line 8, in check
    return func(**kwargs)
  File "c:/Users/ole lukoie/Desktop/my_parser/Yarche/main.py", line 50, in main
    parser.CENTER()
  File "c:\Users\ole lukoie\Desktop\my_parser\Yarche\buld.py", line 36, in CENTER
    self.parse_product_category()
  File "c:\Users\ole lukoie\Desktop\my_parser\Yarche\buld.py", line 103, in parse_product_category
    json=data_for_get_products(category_id=category['id'], limit=category['amount']),
TypeError: 'int' object is not subscriptable
2022-03-27 02:25:40,306 |    ERROR | 'int' object is not subscriptable
Traceback (most recent call last):
  File "c:\Users\ole lukoie\Desktop\my_parser\baseParser\control.py", line 8, in check
    return func(**kwargs)
  File "c:/Users/ole lukoie/Desktop/my_parser/Yarche/main.py", line 50, in main
    parser.CENTER()
  File "c:\Users\ole lukoie\Desktop\my_parser\Yarche\buld.py", line 36, in CENTER
    self.parse_product_category()
  File "c:\Users\ole lukoie\Desktop\my_parser\Yarche\buld.py", line 98, in parse_product_category
    print(category['id'], category['amount'])
TypeError: 'int' object is not subscriptable
2022-03-27 02:26:34,924 |    ERROR | 'int' object is not subscriptable
Traceback (most recent call last):
  File "c:\Users\ole lukoie\Desktop\my_parser\baseParser\control.py", line 8, in check
    return func(**kwargs)
  File "c:/Users/ole lukoie/Desktop/my_parser/Yarche/main.py", line 50, in main
    parser.CENTER()
  File "c:\Users\ole lukoie\Desktop\my_parser\Yarche\buld.py", line 36, in CENTER
    self.parse_product_category()
  File "c:\Users\ole lukoie\Desktop\my_parser\Yarche\buld.py", line 97, in parse_product_category
    print(category['id'], category['amount'])
TypeError: 'int' object is not subscriptable
2022-03-27 02:29:06,428 |    ERROR | 'list'
Traceback (most recent call last):
  File "c:\Users\ole lukoie\Desktop\my_parser\baseParser\control.py", line 8, in check
    return func(**kwargs)
  File "c:/Users/ole lukoie/Desktop/my_parser/Yarche/main.py", line 50, in main
    parser.CENTER()
  File "c:\Users\ole lukoie\Desktop\my_parser\Yarche\buld.py", line 36, in CENTER
    self.parse_product_category()
  File "c:\Users\ole lukoie\Desktop\my_parser\Yarche\buld.py", line 105, in parse_product_category
    self.before_category[index]['products'] = response.json()['data']['list']
KeyError: 'list'
2022-03-27 02:29:34,112 |    ERROR | 'list'
Traceback (most recent call last):
  File "c:\Users\ole lukoie\Desktop\my_parser\baseParser\control.py", line 8, in check
    return func(**kwargs)
  File "c:/Users/ole lukoie/Desktop/my_parser/Yarche/main.py", line 50, in main
    parser.CENTER()
  File "c:\Users\ole lukoie\Desktop\my_parser\Yarche\buld.py", line 36, in CENTER
    self.parse_product_category()
  File "c:\Users\ole lukoie\Desktop\my_parser\Yarche\buld.py", line 106, in parse_product_category
    self.before_category[index]['products'] = response.json()['data']['list']
KeyError: 'list'
